//#include <>
using std::exception;

int main(){

}
